Traceback (most recent call last):
  File "/opt/ros/noetic/lib/python3/dist-packages/rospy/impl/tcpros_service.py", line 465, in _get_service_uri
    self.uri = master.lookupService(self.resolved_name)
  File "/opt/ros/noetic/lib/python3/dist-packages/rosgraph/masterapi.py", line 327, in lookupService
    return self._succeed(self.handle.lookupService(self.caller_id, service))
  File "/opt/ros/noetic/lib/python3/dist-packages/rosgraph/masterapi.py", line 154, in _succeed
    raise Error(msg)
rosgraph.masterapi.MasterError: no provider

During handling of the above exception, another exception occurred:

Traceback (most recent call last):
  File "/opt/ros/noetic/lib/python3/dist-packages/camera_calibration/camera_calibrator.py", line 276, in on_mouse
    if self.do_upload():
  File "/opt/ros/noetic/lib/python3/dist-packages/camera_calibration/camera_calibrator.py", line 233, in do_upload
    response = self.set_left_camera_info_service(info[0])
  File "/opt/ros/noetic/lib/python3/dist-packages/rospy/impl/tcpros_service.py", line 442, in __call__
    return self.call(*args, **kwds)
  File "/opt/ros/noetic/lib/python3/dist-packages/rospy/impl/tcpros_service.py", line 502, in call
    service_uri = self._get_service_uri(request)
  File "/opt/ros/noetic/lib/python3/dist-packages/rospy/impl/tcpros_service.py", line 470, in _get_service_uri
    raise ServiceException("service [%s] unavailable"%self.resolved_name)
rospy.service.ServiceException: service [/left_camera/set_camera_info] unavailable
